<?xml version="1.0" encoding="utf-8"?>
<!--
  scene.xml - Franka Panda pipe-flange inspection scene.

  This version intentionally does not use the provided DH parameters.
  The robot is the Franka Panda model from franka_sim-master, with mesh paths
  corrected for this workspace and a TCP-mounted inspection camera added.
-->
<mujoco model="franka_flange_inspection">
  <compiler angle="radian" autolimits="true"/>
  <option gravity="0 0 -9.81" timestep="0.002" integrator="RK4"/>
  <size nuser_actuator="5"/>
  <statistic extent="1"/>
  <visual>
    <!-- Wide clipping for the interactive world viewer.
         D405 depth rendering overrides this in Python to 0.07 m ~ 0.50 m. -->
    <global offwidth="1280" offheight="800"/>
    <map znear="0.01" zfar="5.00"/>
  </visual>

  <asset>
    <texture name="grid_floor" type="2d" builtin="checker"
             rgb1="0.72 0.72 0.72" rgb2="0.48 0.48 0.48" width="512" height="512"/>
    <material name="floor_mat" texture="grid_floor" texrepeat="8 8" reflectance="0.1"/>
    <texture name="skybox" type="skybox" builtin="gradient"
             rgb1="0.70 0.78 0.90" rgb2="0.20 0.30 0.50" width="512" height="512"/>

    <mesh name="link0_col" file="franka_sim-master/meshes/collision/link0.stl"/>
    <mesh name="link1_col" file="franka_sim-master/meshes/collision/link1.stl"/>
    <mesh name="link2_col" file="franka_sim-master/meshes/collision/link2.stl"/>
    <mesh name="link3_col" file="franka_sim-master/meshes/collision/link3.stl"/>
    <mesh name="link4_col" file="franka_sim-master/meshes/collision/link4.stl"/>
    <mesh name="link5_col" file="franka_sim-master/meshes/collision/link5.stl"/>
    <mesh name="link6_col" file="franka_sim-master/meshes/collision/link6.stl"/>
    <mesh name="link7_col" file="franka_sim-master/meshes/collision/link7.stl"/>
    <mesh name="link0_viz" file="franka_sim-master/meshes/visual/link0.stl"/>
    <mesh name="link1_viz" file="franka_sim-master/meshes/visual/link1.stl"/>
    <mesh name="link2_viz" file="franka_sim-master/meshes/visual/link2.stl"/>
    <mesh name="link3_viz" file="franka_sim-master/meshes/visual/link3.stl"/>
    <mesh name="link3_dark_viz" file="franka_sim-master/meshes/visual/link3_dark.stl" scale="1.01 1.01 1.01"/>
    <mesh name="link4_viz" file="franka_sim-master/meshes/visual/link4.stl"/>
    <mesh name="link4_dark_viz" file="franka_sim-master/meshes/visual/link4_dark.stl" scale="1.01 1.01 1.01"/>
    <mesh name="link5_viz" file="franka_sim-master/meshes/visual/link5.stl"/>
    <mesh name="link5_dark_viz" file="franka_sim-master/meshes/visual/link5_dark.stl" scale="1.01 1.01 1.01"/>
    <mesh name="link6_viz" file="franka_sim-master/meshes/visual/link6.stl"/>
    <mesh name="link6_dark_viz" file="franka_sim-master/meshes/visual/link6_dark.stl" scale="1.01 1.01 1.01"/>
    <mesh name="link7_viz" file="franka_sim-master/meshes/visual/link7.stl"/>
    <mesh name="link7_dark_viz" file="franka_sim-master/meshes/visual/link7_dark.stl" scale="1.01 1.01 1.01"/>
  </asset>

  <default>
    <geom contype="0" conaffinity="0" condim="3"/>
    <site size="0.008" rgba="1 1 0 1" type="sphere"/>
    <default class="panda">
      <joint pos="0 0 0" axis="0 0 1" limited="true"/>
      <position forcelimited="true" ctrllimited="true" user="1002 40 2001 -0.005 0.005"/>
      <default class="panda_viz">
        <geom contype="0" conaffinity="0" group="0" type="mesh" rgba=".92 .92 .95 1"/>
      </default>
      <default class="panda_grey_viz">
        <geom contype="0" conaffinity="0" group="0" type="mesh" rgba=".4 .4 .4 1"/>
      </default>
      <default class="panda_col">
        <geom contype="0" conaffinity="0" group="3" type="mesh" rgba=".5 .6 .7 .25"/>
      </default>
      <default class="panda_arm">
        <joint damping="100"/>
      </default>
      <default class="panda_forearm">
        <joint damping="10"/>
      </default>
    </default>
  </default>

  <worldbody>
    <light name="sun"  pos="0.5 0 3"  dir="0 0 -1" diffuse="0.8 0.8 0.8" castshadow="true"/>
    <light name="fill" pos="-1 1 2"   dir="0.3 -0.3 -1" diffuse="0.3 0.3 0.3" castshadow="false"/>
    <geom name="floor" type="plane" size="4 4 0.1" pos="0 0 0" material="floor_mat" contype="1" conaffinity="1"/>
    <site name="world_origin" pos="0 0 0" size="0.018" rgba="1 1 1 1"/>

    <!-- Franka Panda from franka_sim-master/assets/chain0_nogripper.xml. -->
    <body name="panda0_link0" pos="-0.10 0 0" childclass="panda">
      <!-- Robot base frame marker. Orientation is parallel to the world frame. -->
      <site name="robot_base_origin" pos="0 0 0" size="0.018" rgba="1 1 1 1"/>
      <site name="robot_base_x" pos="0.100 0 0" size="0.005 0.100" euler="0 1.5708 0" rgba="1 0 0 0.9" type="cylinder"/>
      <site name="robot_base_y" pos="0 0.100 0" size="0.005 0.100" euler="1.5708 0 0" rgba="0 1 0 0.9" type="cylinder"/>
      <site name="robot_base_z" pos="0 0 0.100" size="0.005 0.100" rgba="0 0 1 0.9" type="cylinder"/>
      <geom class="panda_viz" mesh="link0_viz"/>
      <geom class="panda_col" mesh="link0_col" mass="2.91242"/>
      <body name="panda0_link1" pos="0 0 0.333">
        <joint name="panda0_joint1" range="-2.8973 2.8973" class="panda_arm"/>
        <geom class="panda_viz" mesh="link1_viz"/>
        <geom class="panda_col" mesh="link1_col" mass="2.7063"/>
        <body name="panda0_link2" pos="0 0 0" quat="0.707107 -0.707107 0 0">
          <joint name="panda0_joint2" range="-1.7628 1.7628" class="panda_arm"/>
          <geom class="panda_viz" mesh="link2_viz"/>
          <geom class="panda_col" mesh="link2_col" mass="2.73046"/>
          <body name="panda0_link3" pos="0 -0.316 0" quat="0.707107 0.707107 0 0">
            <joint name="panda0_joint3" range="-2.8973 2.8973" class="panda_arm"/>
            <geom class="panda_viz" mesh="link3_viz"/>
            <geom class="panda_grey_viz" mesh="link3_dark_viz" pos="0 .001 0"/>
            <geom class="panda_col" mesh="link3_col" mass="2.04104"/>
            <body name="panda0_link4" pos="0.0825 0 0" quat="0.707107 0.707107 0 0">
              <joint name="panda0_joint4" range="-3.0718 -0.0698" class="panda_arm"/>
              <geom class="panda_viz" mesh="link4_viz"/>
              <geom class="panda_grey_viz" mesh="link4_dark_viz"/>
              <geom class="panda_col" mesh="link4_col" mass="2.08129"/>
              <body name="panda0_link5" pos="-0.0825 0.384 0" quat="0.707107 -0.707107 0 0">
                <joint name="panda0_joint5" range="-2.8973 2.8973" class="panda_forearm"/>
                <geom class="panda_viz" mesh="link5_viz"/>
                <geom class="panda_grey_viz" mesh="link5_dark_viz"/>
                <geom class="panda_col" mesh="link5_col" mass="3.00049"/>
                <body name="panda0_link6" pos="0 0 0" euler="1.57 0 1.57">
                  <joint name="panda0_joint6" range="-0.0175 3.7525" class="panda_forearm"/>
                  <geom class="panda_viz" mesh="link6_viz"/>
                  <geom class="panda_grey_viz" mesh="link6_dark_viz"/>
                  <geom class="panda_col" mesh="link6_col" mass="1.3235"/>
                  <body name="panda0_link7" pos="0.088 0 0" euler="1.57 0 0.7854">
                    <joint name="panda0_joint7" range="-2.8973 2.8973" class="panda_forearm"/>
                    <geom class="panda_viz" mesh="link7_viz" rgba=".8 .8 .82 1"/>
                    <geom class="panda_grey_viz" mesh="link7_dark_viz" pos="0 0 -.0008"/>
                    <geom class="panda_col" mesh="link7_col" mass="0.2"/>

                    <body name="tool" pos="0 0 0.210" euler="0 0 -0.785398">
                      <site name="tcp" pos="0 0 0" size="0.012" rgba="1 1 0 0"/>
                      <site name="tcp_x" pos="0.060 0 0" size="0.004 0.060" euler="0 1.5708 0" rgba="1 0 0 0" type="cylinder"/>
                      <site name="tcp_y" pos="0 0.060 0" size="0.004 0.060" euler="1.5708 0 0" rgba="0 1 0 0" type="cylinder"/>
                      <site name="tcp_z" pos="0 0 0.060" size="0.004 0.060" rgba="0 0 1 0" type="cylinder"/>
                      <geom name="inspection_camera_body" type="box" size="0.022 0.018 0.026" pos="0 0 -0.100" rgba="0.05 0.05 0.05 1"/>
                      <geom name="inspection_camera_lens" type="cylinder" size="0.010 0.012" pos="0 0 -0.128" rgba="0.01 0.01 0.01 1"/>
                      <site name="camera_optical_center" pos="0 0 -0.100" size="0.010" rgba="1 0.6 0 0"/>
                      <camera name="inspection_camera" pos="0 0 -0.100" euler="0 0 0" fovy="60" mode="fixed"/>
                      <!-- RealSense D405 template: mounted 100 mm behind TCP along TCP -z.
                           euler="3.14159 0 0" makes the MuJoCo camera optical axis
                           point along TCP +z, which is aimed at the pipe/flange seam. -->
                      <camera name="d405_camera" pos="0 0 -0.100" euler="3.14159 0 0" fovy="58" mode="fixed"/>
                    </body>
                  </body>
                </body>
              </body>
            </body>
          </body>
        </body>
      </body>
    </body>

    <!-- Pipe-flange assembly. Pipe axis is world +x; flange face center is (0.69, 0, 0.57). -->
    <body name="pipe_flange_assembly" pos="0.5650 0.0000 0.5700" euler="0 1.5708 0">
      <geom name="pipe_outer" type="cylinder" pos="0 0 0" size="0.03025 0.1250" rgba="0.55 0.55 0.60 1" contype="1" conaffinity="1"/>
      <geom name="pipe_bore" type="cylinder" pos="0 0 0" size="0.0271 0.1260" rgba="0.12 0.12 0.12 1"/>
      <geom name="flange_disc" type="cylinder" pos="0 0 0.13775" size="0.0760 0.01275" rgba="0.45 0.50 0.56 1" contype="1" conaffinity="1"/>
      <geom name="flange_bore" type="cylinder" pos="0 0 0.13775" size="0.03025 0.01375" rgba="0.11 0.11 0.11 1"/>
      <geom name="raised_face" type="cylinder" pos="0 0 0.1515" size="0.0502 0.0010" rgba="0.62 0.64 0.67 1"/>
      <geom name="raised_bore" type="cylinder" pos="0 0 0.1515" size="0.03025 0.0015" rgba="0.10 0.10 0.10 1"/>
      <geom name="bolt_0" type="cylinder" pos=" 0.0628  0.0000 0.1545" size="0.0093 0.0025" rgba="0.22 0.22 0.22 1"/>
      <geom name="bolt_1" type="cylinder" pos=" 0.0444  0.0444 0.1545" size="0.0093 0.0025" rgba="0.22 0.22 0.22 1"/>
      <geom name="bolt_2" type="cylinder" pos=" 0.0000  0.0628 0.1545" size="0.0093 0.0025" rgba="0.22 0.22 0.22 1"/>
      <geom name="bolt_3" type="cylinder" pos="-0.0444  0.0444 0.1545" size="0.0093 0.0025" rgba="0.22 0.22 0.22 1"/>
      <geom name="bolt_4" type="cylinder" pos="-0.0628  0.0000 0.1545" size="0.0093 0.0025" rgba="0.22 0.22 0.22 1"/>
      <geom name="bolt_5" type="cylinder" pos="-0.0444 -0.0444 0.1545" size="0.0093 0.0025" rgba="0.22 0.22 0.22 1"/>
      <geom name="bolt_6" type="cylinder" pos=" 0.0000 -0.0628 0.1545" size="0.0093 0.0025" rgba="0.22 0.22 0.22 1"/>
      <geom name="bolt_7" type="cylinder" pos=" 0.0444 -0.0444 0.1545" size="0.0093 0.0025" rgba="0.22 0.22 0.22 1"/>
      <geom name="hole_0" type="cylinder" pos=" 0.0628  0.0000 0.1535" size="0.0063 0.0012" rgba="0.04 0.04 0.04 1"/>
      <geom name="hole_1" type="cylinder" pos=" 0.0444  0.0444 0.1535" size="0.0063 0.0012" rgba="0.04 0.04 0.04 1"/>
      <geom name="hole_2" type="cylinder" pos=" 0.0000  0.0628 0.1535" size="0.0063 0.0012" rgba="0.04 0.04 0.04 1"/>
      <geom name="hole_3" type="cylinder" pos="-0.0444  0.0444 0.1535" size="0.0063 0.0012" rgba="0.04 0.04 0.04 1"/>
      <geom name="hole_4" type="cylinder" pos="-0.0628  0.0000 0.1535" size="0.0063 0.0012" rgba="0.04 0.04 0.04 1"/>
      <geom name="hole_5" type="cylinder" pos="-0.0444 -0.0444 0.1535" size="0.0063 0.0012" rgba="0.04 0.04 0.04 1"/>
      <geom name="hole_6" type="cylinder" pos=" 0.0000 -0.0628 0.1535" size="0.0063 0.0012" rgba="0.04 0.04 0.04 1"/>
      <geom name="hole_7" type="cylinder" pos=" 0.0444 -0.0444 0.1535" size="0.0063 0.0012" rgba="0.04 0.04 0.04 1"/>
      <site name="flange_center" pos="0 0 0.1250" size="0.013" rgba="1 0 0 0"/>
      <site name="flange_frame_y" pos="0 0.08 0.1250" size="0.005 0.08" euler="1.5708 0 0" rgba="0 1 0 0" type="cylinder"/>
      <site name="flange_frame_x" pos="0.08 0 0.1250" size="0.005 0.08" euler="0 1.5708 0" rgba="1 0 0 0" type="cylinder"/>
      <site name="flange_frame_z" pos="0 0 0.2050" size="0.005 0.08" rgba="0 0 1 0" type="cylinder"/>
    </body>

    <body name="traj_markers" pos="0 0 0">
      <site name="wp_00" pos="0.4000  0.1652 0.5700" size="0.010" rgba="0 1 1 0.8"/>
      <site name="wp_01" pos="0.4000  0.1627 0.5987" size="0.010" rgba="0 1 1 0.8"/>
      <site name="wp_02" pos="0.4000  0.1553 0.6265" size="0.010" rgba="0 1 1 0.8"/>
      <site name="wp_03" pos="0.4000  0.1431 0.6526" size="0.010" rgba="0 1 1 0.8"/>
      <site name="wp_04" pos="0.4000  0.1266 0.6762" size="0.010" rgba="0 1 1 0.8"/>
      <site name="wp_05" pos="0.4000  0.1062 0.6966" size="0.010" rgba="0 1 1 0.8"/>
      <site name="wp_06" pos="0.4000  0.0826 0.7131" size="0.010" rgba="0 1 1 0.8"/>
      <site name="wp_07" pos="0.4000  0.0565 0.7253" size="0.010" rgba="0 1 1 0.8"/>
      <site name="wp_08" pos="0.4000  0.0287 0.7327" size="0.010" rgba="0 1 1 0.8"/>
      <site name="wp_09" pos="0.4000  0.0000 0.7352" size="0.010" rgba="0 1 1 0.8"/>
      <site name="wp_10" pos="0.4000 -0.0287 0.7327" size="0.010" rgba="0 1 1 0.8"/>
      <site name="wp_11" pos="0.4000 -0.0565 0.7253" size="0.010" rgba="0 1 1 0.8"/>
      <site name="wp_12" pos="0.4000 -0.0826 0.7131" size="0.010" rgba="0 1 1 0.8"/>
      <site name="wp_13" pos="0.4000 -0.1062 0.6966" size="0.010" rgba="0 1 1 0.8"/>
      <site name="wp_14" pos="0.4000 -0.1266 0.6762" size="0.010" rgba="0 1 1 0.8"/>
      <site name="wp_15" pos="0.4000 -0.1431 0.6526" size="0.010" rgba="0 1 1 0.8"/>
      <site name="wp_16" pos="0.4000 -0.1553 0.6265" size="0.010" rgba="0 1 1 0.8"/>
      <site name="wp_17" pos="0.4000 -0.1627 0.5987" size="0.010" rgba="0 1 1 0.8"/>
      <site name="wp_18" pos="0.4000 -0.1652 0.5700" size="0.010" rgba="0 1 1 0.8"/>
      <site name="wp_19" pos="0.4000 -0.1627 0.5413" size="0.010" rgba="0 1 1 0.8"/>
      <site name="wp_20" pos="0.4000 -0.1553 0.5135" size="0.010" rgba="0 1 1 0.8"/>
      <site name="wp_21" pos="0.4000 -0.1431 0.4874" size="0.010" rgba="0 1 1 0.8"/>
      <site name="wp_22" pos="0.4000 -0.1266 0.4638" size="0.010" rgba="0 1 1 0.8"/>
      <site name="wp_23" pos="0.4000 -0.1062 0.4434" size="0.010" rgba="0 1 1 0.8"/>
      <site name="wp_24" pos="0.4000 -0.0826 0.4269" size="0.010" rgba="0 1 1 0.8"/>
      <site name="wp_25" pos="0.4000 -0.0565 0.4147" size="0.010" rgba="0 1 1 0.8"/>
      <site name="wp_26" pos="0.4000 -0.0287 0.4073" size="0.010" rgba="0 1 1 0.8"/>
      <site name="wp_27" pos="0.4000 -0.0000 0.4048" size="0.010" rgba="0 1 1 0.8"/>
      <site name="wp_28" pos="0.4000  0.0287 0.4073" size="0.010" rgba="0 1 1 0.8"/>
      <site name="wp_29" pos="0.4000  0.0565 0.4147" size="0.010" rgba="0 1 1 0.8"/>
      <site name="wp_30" pos="0.4000  0.0826 0.4269" size="0.010" rgba="0 1 1 0.8"/>
      <site name="wp_31" pos="0.4000  0.1062 0.4434" size="0.010" rgba="0 1 1 0.8"/>
      <site name="wp_32" pos="0.4000  0.1266 0.4638" size="0.010" rgba="0 1 1 0.8"/>
      <site name="wp_33" pos="0.4000  0.1431 0.4874" size="0.010" rgba="0 1 1 0.8"/>
      <site name="wp_34" pos="0.4000  0.1553 0.5135" size="0.010" rgba="0 1 1 0.8"/>
      <site name="wp_35" pos="0.4000  0.1627 0.5413" size="0.010" rgba="0 1 1 0.8"/>
    </body>
  </worldbody>

  <actuator>
    <position name="panda0_joint1" joint="panda0_joint1" class="panda" kp="870" kv="80" forcerange="-87 87" ctrlrange="-2.8973 2.8973"/>
    <position name="panda0_joint2" joint="panda0_joint2" class="panda" kp="870" kv="80" forcerange="-87 87" ctrlrange="-1.7628 1.7628"/>
    <position name="panda0_joint3" joint="panda0_joint3" class="panda" kp="870" kv="80" forcerange="-87 87" ctrlrange="-2.8973 2.8973"/>
    <position name="panda0_joint4" joint="panda0_joint4" class="panda" kp="870" kv="80" forcerange="-87 87" ctrlrange="-3.0718 -0.0698"/>
    <position name="panda0_joint5" joint="panda0_joint5" class="panda" kp="120" kv="20" forcerange="-12 12" ctrlrange="-2.8973 2.8973"/>
    <position name="panda0_joint6" joint="panda0_joint6" class="panda" kp="120" kv="20" forcerange="-12 12" ctrlrange="-0.0175 3.7525"/>
    <position name="panda0_joint7" joint="panda0_joint7" class="panda" kp="120" kv="20" forcerange="-12 12" ctrlrange="-2.8973 2.8973"/>
  </actuator>

  <sensor>
    <jointpos name="q1" joint="panda0_joint1"/>
    <jointpos name="q2" joint="panda0_joint2"/>
    <jointpos name="q3" joint="panda0_joint3"/>
    <jointpos name="q4" joint="panda0_joint4"/>
    <jointpos name="q5" joint="panda0_joint5"/>
    <jointpos name="q6" joint="panda0_joint6"/>
    <jointpos name="q7" joint="panda0_joint7"/>
    <framepos name="tcp_pos" objtype="site" objname="tcp"/>
    <framequat name="tcp_quat" objtype="site" objname="tcp"/>
    <framepos name="camera_pos" objtype="site" objname="camera_optical_center"/>
    <framequat name="camera_quat" objtype="site" objname="camera_optical_center"/>
  </sensor>

  <keyframe>
    <key name="home" qpos="0 -0.785 0 -2.356 0 1.571 0.785"/>
    <key name="inspect_wp1" qpos="2.254078 -1.665471 -1.329159 -2.057323 -0.152227 0.598290 0.638535"/>
  </keyframe>
</mujoco>
