<mujoco model="serial6r_posctrl">
  <compiler angle="radian" autolimits="true"/>
  <option integrator="implicitfast" gravity="0 0 -9.81" timestep="0.002"/>
  <default>
    <joint type="hinge" axis="0 0 1" damping="1.0" frictionloss="0.1" range="-3.14159 3.14159"/>
    <geom density="2000"/>
    <position kp="250" kv="25" ctrlrange="-3.14159 3.14159" forcerange="-150 150"/>
  </default>
  <worldbody>
    <light pos="0 0 2" dir="0 0 -1" diffuse="1 1 1"/>
    <geom name="floor" type="plane" size="2 2 0.1" rgba="0.2 0.2 0.2 1" density="0"/>
    <body name="base" pos="0 0 0">
      <geom name="foot" type="cylinder" fromto="0 0 0 0 0 0.02" size="0.07" rgba="0.25 0.25 0.3 1"/>
      <geom name="column" type="cylinder" fromto="0 0 0.02 0 0 0.0948" size="0.03" rgba="0.3 0.3 0.35 1"/>
      <body name="link1" pos="0.000000 0.000000 0.144763" quat="0.002699 0.000000 0.000000 -0.999996">
        <joint name="q1"/>
        <geom name="link1_g" type="capsule" fromto="0 0 0 -0.061099 0.000000 0.132184" size="0.025" rgba="0.85 0.3 0.3 1"/>
        <geom name="j1_g" type="cylinder" size="0.04 0.03" rgba="0.12 0.12 0.12 1"/>
        <body name="link2" pos="-0.061099 0.000000 0.132184" quat="0.707799 -0.706413 0.000828 0.000830">
          <joint name="q2"/>
          <geom name="link2_g" type="capsule" fromto="0 0 0 0.345932 0.000000 0.091502" size="0.025" rgba="0.85 0.55 0.2 1"/>
          <geom name="j2_g" type="cylinder" size="0.04 0.03" rgba="0.12 0.12 0.12 1"/>
          <body name="link3" pos="0.345932 0.000000 0.091502" quat="0.704644 -0.001551 -0.001561 -0.709558">
            <joint name="q3"/>
            <geom name="link3_g" type="capsule" fromto="0 0 0 0.103901 0.000000 0.005000" size="0.025" rgba="0.8 0.8 0.25 1"/>
            <geom name="j3_g" type="cylinder" size="0.04 0.03" rgba="0.12 0.12 0.12 1"/>
            <body name="link4" pos="0.103901 0.000000 0.005000" quat="0.705697 0.708499 0.003291 -0.003278">
              <joint name="q4"/>
              <geom name="link4_g" type="capsule" fromto="0 0 0 -0.000588 0.000000 0.344628" size="0.025" rgba="0.3 0.75 0.4 1"/>
              <geom name="j4_g" type="cylinder" size="0.04 0.03" rgba="0.12 0.12 0.12 1"/>
              <body name="link5" pos="-0.000588 0.000000 0.344628" quat="0.013053 -0.013195 -0.710781 -0.703168">
                <joint name="q5"/>
                <geom name="link5_g" type="capsule" fromto="0 0 0 0.074472 0.000000 -0.024818" size="0.025" rgba="0.3 0.6 0.85 1"/>
                <geom name="j5_g" type="cylinder" size="0.04 0.03" rgba="0.12 0.12 0.12 1"/>
                <body name="link6" pos="0.074472 0.000000 -0.024818" quat="0.501595 -0.493208 0.498313 0.506787">
                  <joint name="q6"/>
                  <geom name="link6_g" type="capsule" fromto="0 0 0 0.070882 -0.244194 0.030304" size="0.025" rgba="0.6 0.4 0.85 1"/>
                  <geom name="j6_g" type="cylinder" size="0.04 0.03" rgba="0.12 0.12 0.12 1"/>
                  <body name="ee" pos="0.070882 -0.244194 0.030304" quat="0.724562 -0.689210 0.000000 0.000000">
                    <site name="tcp" size="0.004" rgba="1 0 0 1"/>
                    <body name="d405_mount" pos="-0.03667 0.00798 0.05980" quat="0.68961 0.06423 -0.13501 -0.70858">
                      <inertial pos="0 0 0" mass="0.05" diaginertia="1e-5 1e-5 1e-5"/>
                      <site name="camera_optical_center" pos="0 0 0" size="0.010" rgba="1 0.6 0 0.9"/>
                      <camera name="ee_cam" mode="fixed" pos="0 0 0" fovy="65"/>
                    </body>
                  </body>
                </body>
              </body>
            </body>
          </body>
        </body>
      </body>
    </body>
  </worldbody>
  <actuator>
    <position name="p1" joint="q1"/>
    <position name="p2" joint="q2"/>
    <position name="p3" joint="q3"/>
    <position name="p4" joint="q4"/>
    <position name="p5" joint="q5"/>
    <position name="p6" joint="q6"/>
  </actuator>
  <sensor>
    <framepos name="tcp_pos" objtype="site" objname="tcp"/>
    <framequat name="tcp_quat" objtype="site" objname="tcp"/>
    <jointpos name="q1p" joint="q1"/>
  </sensor>
  <keyframe>
    <key name="ready" qpos="0.000000 -0.600000 0.600000 0.000000 0.600000 0.000000" ctrl="0.000000 -0.600000 0.600000 0.000000 0.600000 0.000000"/>
  </keyframe>
</mujoco>