<?xml version="1.0" encoding="utf-8"?>
<mujoco model="arm6dof_dh2mujoco">
  <compiler angle="radian" autolimits="true" inertiafromgeom="auto" />
  <option timestep="0.002" integrator="implicitfast" gravity="0 0 -9.81" />
  <statistic center="0.15 0 0.15" extent="1.2" />
  <default>
    <joint type="hinge" damping="2" armature="0.05" frictionloss="0.1" />
    <geom contype="0" conaffinity="0" friction="1 0.5 0.05" />
    <position ctrllimited="true" />
    <site size="0.008" rgba="1 1 0 1" type="sphere" />
  </default>
  <worldbody>
    <geom name="ground" type="plane" pos="0 0 -0.02" size="1.2 1.2 0.02" rgba="0.82 0.82 0.82 1" />
    <geom name="world_x" type="capsule" fromto="0 0 0 0.15 0 0" size="0.005" rgba="1 0 0 1" contype="0" conaffinity="0" group="0" />
    <geom name="world_y" type="capsule" fromto="0 0 0 0 0.15 0" size="0.005" rgba="0 0.8 0 1" contype="0" conaffinity="0" group="0" />
    <geom name="world_z" type="capsule" fromto="0 0 0 0 0 0.15" size="0.005" rgba="0.1 0.2 1 1" contype="0" conaffinity="0" group="0" />
    <body name="robot_base" pos="0 0 0">
      <inertial pos="0 0 0" mass="0.01" diaginertia="1e-6 1e-6 1e-6" />
      <body name="pre_1" pos="-0.061099 0 0" quat="-0.00191047023 0.00190673066 0.706411142 0.70779659">
        <inertial pos="0 0 0" mass="0.02" diaginertia="1e-5 1e-5 1e-5" />
        <joint name="joint1" type="hinge" axis="0 0 1" range="-3.14159265 3.14159265" />
        <geom name="joint1_g" type="cylinder" fromto="0 0 -0.028 0 0 0.028" size="0.022" mass="0.05" rgba="0.2 0.2 0.25 1" contype="2" conaffinity="1" />
        <geom name="pre1_axis_x" type="capsule" fromto="0 0 0 0.06 0 0" size="0.0042" rgba="1 0 0 1" contype="0" conaffinity="0" group="3" />
        <geom name="pre1_axis_y" type="capsule" fromto="0 0 0 0 0.06 0" size="0.0042" rgba="0 0.8 0 1" contype="0" conaffinity="0" group="3" />
        <geom name="pre1_axis_z" type="capsule" fromto="0 0 0 0 0 0.06" size="0.0042" rgba="0.1 0.2 1 1" contype="0" conaffinity="0" group="3" />
        <body name="link1" pos="0 0 0.132184" quat="1 0 0 0">
          <inertial pos="0 0 0" mass="0.08" diaginertia="3e-5 3e-5 3e-5" />
          <geom name="link1_geom" type="capsule" fromto="0 0 0 0 0 0.132184" size="0.014" rgba="0.65 0.45 0.25 0.7" contype="2" conaffinity="1" />
          <body name="pre_2" pos="0.345932 0 0" quat="0.999996892 -0.00220049671 2.57898333e-06 0.00117199689">
            <inertial pos="0 0 0" mass="0.02" diaginertia="1e-5 1e-5 1e-5" />
            <joint name="joint2" type="hinge" axis="0 0 1" range="-3.14159265 3.14159265" />
            <geom name="joint2_g" type="cylinder" fromto="0 0 -0.028 0 0 0.028" size="0.022" mass="0.05" rgba="0.2 0.2 0.25 1" contype="2" conaffinity="1" />
            <geom name="pre2_axis_x" type="capsule" fromto="0 0 0 0.06 0 0" size="0.0042" rgba="1 0 0 1" contype="0" conaffinity="0" group="3" />
            <geom name="pre2_axis_y" type="capsule" fromto="0 0 0 0 0.06 0" size="0.0042" rgba="0 0.8 0 1" contype="0" conaffinity="0" group="3" />
            <geom name="pre2_axis_z" type="capsule" fromto="0 0 0 0 0 0.06" size="0.0042" rgba="0.1 0.2 1 1" contype="0" conaffinity="0" group="3" />
            <body name="link2" pos="0 0 0.091502" quat="1 0 0 0">
              <inertial pos="0 0 0" mass="0.08" diaginertia="3e-5 3e-5 3e-5" />
              <geom name="link2_geom" type="capsule" fromto="0 0 0 0 0 0.091502" size="0.014" rgba="0.65 0.45 0.25 0.7" contype="2" conaffinity="1" />
              <body name="pre_3" pos="0.103901 0 0" quat="0.49727162 0.499246059 0.502727266 -0.500739059">
                <inertial pos="0 0 0" mass="0.02" diaginertia="1e-5 1e-5 1e-5" />
                <joint name="joint3" type="hinge" axis="0 0 1" range="-3.14159265 3.14159265" />
                <geom name="joint3_g" type="cylinder" fromto="0 0 -0.028 0 0 0.028" size="0.022" mass="0.05" rgba="0.2 0.2 0.25 1" contype="2" conaffinity="1" />
                <geom name="pre3_axis_x" type="capsule" fromto="0 0 0 0.06 0 0" size="0.0042" rgba="1 0 0 1" contype="0" conaffinity="0" group="3" />
                <geom name="pre3_axis_y" type="capsule" fromto="0 0 0 0 0.06 0" size="0.0042" rgba="0 0.8 0 1" contype="0" conaffinity="0" group="3" />
                <geom name="pre3_axis_z" type="capsule" fromto="0 0 0 0 0 0.06" size="0.0042" rgba="0.1 0.2 1 1" contype="0" conaffinity="0" group="3" />
                <body name="link3" pos="0 0 0.005" quat="1 0 0 0">
                  <inertial pos="0 0 0" mass="0.08" diaginertia="3e-5 3e-5 3e-5" />
                  <geom name="link3_geom" type="capsule" fromto="0 0 0 0 0 0.005" size="0.014" rgba="0.65 0.45 0.25 0.7" contype="2" conaffinity="1" />
                  <body name="pre_4" pos="-0.000588 0 0" quat="0.703282019 -0.710895795 -0.00330177926 -0.00326641682">
                    <inertial pos="0 0 0" mass="0.02" diaginertia="1e-5 1e-5 1e-5" />
                    <joint name="joint4" type="hinge" axis="0 0 1" range="-3.14159265 3.14159265" />
                    <geom name="joint4_g" type="cylinder" fromto="0 0 -0.028 0 0 0.028" size="0.022" mass="0.05" rgba="0.2 0.2 0.25 1" contype="2" conaffinity="1" />
                    <geom name="pre4_axis_x" type="capsule" fromto="0 0 0 0.06 0 0" size="0.0042" rgba="1 0 0 1" contype="0" conaffinity="0" group="3" />
                    <geom name="pre4_axis_y" type="capsule" fromto="0 0 0 0 0.06 0" size="0.0042" rgba="0 0.8 0 1" contype="0" conaffinity="0" group="3" />
                    <geom name="pre4_axis_z" type="capsule" fromto="0 0 0 0 0 0.06" size="0.0042" rgba="0.1 0.2 1 1" contype="0" conaffinity="0" group="3" />
                    <body name="link4" pos="0 0 0.344628" quat="1 0 0 0">
                      <inertial pos="0 0 0" mass="0.08" diaginertia="3e-5 3e-5 3e-5" />
                      <geom name="link4_geom" type="capsule" fromto="0 0 0 0 0 0.344628" size="0.014" rgba="0.65 0.45 0.25 0.7" contype="2" conaffinity="1" />
                      <body name="pre_5" pos="0.074472 0 0" quat="0.013234257 -0.0130129832 -0.700999927 -0.712919784">
                        <inertial pos="0 0 0" mass="0.02" diaginertia="1e-5 1e-5 1e-5" />
                        <joint name="joint5" type="hinge" axis="0 0 1" range="-3.14159265 3.14159265" />
                        <geom name="joint5_g" type="cylinder" fromto="0 0 -0.028 0 0 0.028" size="0.022" mass="0.05" rgba="0.2 0.2 0.25 1" contype="2" conaffinity="1" />
                        <geom name="pre5_axis_x" type="capsule" fromto="0 0 0 0.06 0 0" size="0.0042" rgba="1 0 0 1" contype="0" conaffinity="0" group="3" />
                        <geom name="pre5_axis_y" type="capsule" fromto="0 0 0 0 0.06 0" size="0.0042" rgba="0 0.8 0 1" contype="0" conaffinity="0" group="3" />
                        <geom name="pre5_axis_z" type="capsule" fromto="0 0 0 0 0 0.06" size="0.0042" rgba="0.1 0.2 1 1" contype="0" conaffinity="0" group="3" />
                        <body name="link5" pos="0 0 -0.024818" quat="1 0 0 0">
                          <inertial pos="0 0 0" mass="0.08" diaginertia="3e-5 3e-5 3e-5" />
                          <geom name="link5_geom" type="capsule" fromto="0 0 0 0 0 -0.024818" size="0.014" rgba="0.65 0.45 0.25 0.7" contype="2" conaffinity="1" />
                          <body name="pre_6" pos="0.070882 0 0" quat="0.509697788 -0.484829268 0.489847765 0.514973701">
                            <inertial pos="0 0 0" mass="0.02" diaginertia="1e-5 1e-5 1e-5" />
                            <joint name="joint6" type="hinge" axis="0 0 1" range="-3.14159265 3.14159265" />
                            <geom name="joint6_g" type="cylinder" fromto="0 0 -0.028 0 0 0.028" size="0.022" mass="0.05" rgba="0.2 0.2 0.25 1" contype="2" conaffinity="1" />
                            <geom name="pre6_axis_x" type="capsule" fromto="0 0 0 0.06 0 0" size="0.0042" rgba="1 0 0 1" contype="0" conaffinity="0" group="3" />
                            <geom name="pre6_axis_y" type="capsule" fromto="0 0 0 0 0.06 0" size="0.0042" rgba="0 0.8 0 1" contype="0" conaffinity="0" group="3" />
                            <geom name="pre6_axis_z" type="capsule" fromto="0 0 0 0 0 0.06" size="0.0042" rgba="0.1 0.2 1 1" contype="0" conaffinity="0" group="3" />
                            <body name="link6" pos="0 0 0.042524" quat="1 0 0 0">
                              <inertial pos="0 0 0" mass="0.08" diaginertia="3e-5 3e-5 3e-5" />
                              <geom name="link6_geom" type="capsule" fromto="0 0 0 0 0 0.042524" size="0.014" rgba="0.65 0.45 0.25 0.7" contype="2" conaffinity="1" />
                              <body name="ee_pre_1" pos="0 0 0" quat="0.707106897 0 0 -0.707106666">
                                <inertial pos="0 0 0" mass="0.01" diaginertia="1e-6 1e-6 1e-6" />
                                <body name="ee_post_1" pos="0 0 -0.2445" quat="1 0 0 0">
                                  <inertial pos="0 0 0" mass="0.01" diaginertia="1e-6 1e-6 1e-6" />
                                  <site name="ee" size="0.012" rgba="1 0 1 1" />
                                </body>
                              </body>
                            </body>
                          </body>
                        </body>
                      </body>
                    </body>
                  </body>
                </body>
              </body>
            </body>
          </body>
        </body>
      </body>
    </body>
  </worldbody>
  <actuator>
    <position name="q1_pos" joint="joint1" kp="80" ctrlrange="-3.14159265 3.14159265" ctrllimited="true" />
    <position name="q2_pos" joint="joint2" kp="80" ctrlrange="-3.14159265 3.14159265" ctrllimited="true" />
    <position name="q3_pos" joint="joint3" kp="80" ctrlrange="-3.14159265 3.14159265" ctrllimited="true" />
    <position name="q4_pos" joint="joint4" kp="60" ctrlrange="-3.14159265 3.14159265" ctrllimited="true" />
    <position name="q5_pos" joint="joint5" kp="45" ctrlrange="-3.14159265 3.14159265" ctrllimited="true" />
    <position name="q6_pos" joint="joint6" kp="35" ctrlrange="-3.14159265 3.14159265" ctrllimited="true" />
  </actuator>
  <sensor>
    <jointpos name="q1" joint="joint1" />
    <jointvel name="dq1" joint="joint1" />
    <jointpos name="q2" joint="joint2" />
    <jointvel name="dq2" joint="joint2" />
    <jointpos name="q3" joint="joint3" />
    <jointvel name="dq3" joint="joint3" />
    <jointpos name="q4" joint="joint4" />
    <jointvel name="dq4" joint="joint4" />
    <jointpos name="q5" joint="joint5" />
    <jointvel name="dq5" joint="joint5" />
    <jointpos name="q6" joint="joint6" />
    <jointvel name="dq6" joint="joint6" />
    <framepos name="ee_pos" objtype="site" objname="ee" />
    <framequat name="ee_quat" objtype="site" objname="ee" />
  </sensor>
  <keyframe>
    <key name="home" qpos="0 0 0 0 0 0" ctrl="0 0 0 0 0 0" />
  </keyframe>
</mujoco>
